/home/feic/miniforge3/envs/open_r1/lib/python3.11/site-packages/transformers/utils/hub.py:106: FutureWarning: Using `TRANSFORMERS_CACHE` is deprecated and will be removed in v5 of Transformers. Use `HF_HOME` instead.
  warnings.warn(
2025-04-28 14:31:20,584 - __main__ - INFO - Using model type: qwen2.5-7b for story generation
2025-04-28 14:31:20,586 - __main__ - INFO - Loading model and tokenizer for Qwen/Qwen2.5-7B-Instruct...
Traceback (most recent call last):
  File "/home/feic/miniforge3/envs/open_r1/lib/python3.11/site-packages/huggingface_hub/utils/_http.py", line 409, in hf_raise_for_status
    response.raise_for_status()
  File "/home/feic/miniforge3/envs/open_r1/lib/python3.11/site-packages/requests/models.py", line 1024, in raise_for_status
    raise HTTPError(http_error_msg, response=self)
requests.exceptions.HTTPError: 401 Client Error: Unauthorized for url: https://huggingface.co/Qwen/Qwen2.5-7B-Instruct/resolve/main/config.json

The above exception was the direct cause of the following exception:

Traceback (most recent call last):
  File "/home/feic/miniforge3/envs/open_r1/lib/python3.11/site-packages/transformers/utils/hub.py", line 342, in cached_file
    resolved_file = hf_hub_download(
                    ^^^^^^^^^^^^^^^^
  File "/home/feic/miniforge3/envs/open_r1/lib/python3.11/site-packages/huggingface_hub/utils/_validators.py", line 114, in _inner_fn
    return fn(*args, **kwargs)
           ^^^^^^^^^^^^^^^^^^^
  File "/home/feic/miniforge3/envs/open_r1/lib/python3.11/site-packages/huggingface_hub/file_download.py", line 862, in hf_hub_download
    return _hf_hub_download_to_cache_dir(
           ^^^^^^^^^^^^^^^^^^^^^^^^^^^^^^
  File "/home/feic/miniforge3/envs/open_r1/lib/python3.11/site-packages/huggingface_hub/file_download.py", line 969, in _hf_hub_download_to_cache_dir
    _raise_on_head_call_error(head_call_error, force_download, local_files_only)
  File "/home/feic/miniforge3/envs/open_r1/lib/python3.11/site-packages/huggingface_hub/file_download.py", line 1486, in _raise_on_head_call_error
    raise head_call_error
  File "/home/feic/miniforge3/envs/open_r1/lib/python3.11/site-packages/huggingface_hub/file_download.py", line 1376, in _get_metadata_or_catch_error
    metadata = get_hf_file_metadata(
               ^^^^^^^^^^^^^^^^^^^^^
  File "/home/feic/miniforge3/envs/open_r1/lib/python3.11/site-packages/huggingface_hub/utils/_validators.py", line 114, in _inner_fn
    return fn(*args, **kwargs)
           ^^^^^^^^^^^^^^^^^^^
  File "/home/feic/miniforge3/envs/open_r1/lib/python3.11/site-packages/huggingface_hub/file_download.py", line 1296, in get_hf_file_metadata
    r = _request_wrapper(
        ^^^^^^^^^^^^^^^^^
  File "/home/feic/miniforge3/envs/open_r1/lib/python3.11/site-packages/huggingface_hub/file_download.py", line 280, in _request_wrapper
    response = _request_wrapper(
               ^^^^^^^^^^^^^^^^^
  File "/home/feic/miniforge3/envs/open_r1/lib/python3.11/site-packages/huggingface_hub/file_download.py", line 304, in _request_wrapper
    hf_raise_for_status(response)
  File "/home/feic/miniforge3/envs/open_r1/lib/python3.11/site-packages/huggingface_hub/utils/_http.py", line 481, in hf_raise_for_status
    raise _format(HfHubHTTPError, str(e), response) from e
huggingface_hub.errors.HfHubHTTPError: 401 Client Error: Unauthorized for url: https://huggingface.co/Qwen/Qwen2.5-7B-Instruct/resolve/main/config.json (Request ID: Root=1-680f9139-5a4fc62c17b112545aa7820f;21437377-6298-49bb-a391-33a92fa7f357)

Invalid credentials in Authorization header

During handling of the above exception, another exception occurred:

Traceback (most recent call last):
  File "/home/feic/pjs/CS283/CS283/src/main_with_opensource_model.py", line 273, in <module>
    model, tokenizer = load_model_and_tokenizer(model_type)
                       ^^^^^^^^^^^^^^^^^^^^^^^^^^^^^^^^^^^^
  File "/home/feic/pjs/CS283/CS283/src/main_with_opensource_model.py", line 49, in load_model_and_tokenizer
    tokenizer = AutoTokenizer.from_pretrained(model_name)
                ^^^^^^^^^^^^^^^^^^^^^^^^^^^^^^^^^^^^^^^^^
  File "/home/feic/miniforge3/envs/open_r1/lib/python3.11/site-packages/transformers/models/auto/tokenization_auto.py", line 901, in from_pretrained
    config = AutoConfig.from_pretrained(
             ^^^^^^^^^^^^^^^^^^^^^^^^^^^
  File "/home/feic/miniforge3/envs/open_r1/lib/python3.11/site-packages/transformers/models/auto/configuration_auto.py", line 1075, in from_pretrained
    config_dict, unused_kwargs = PretrainedConfig.get_config_dict(pretrained_model_name_or_path, **kwargs)
                                 ^^^^^^^^^^^^^^^^^^^^^^^^^^^^^^^^^^^^^^^^^^^^^^^^^^^^^^^^^^^^^^^^^^^^^^^^^
  File "/home/feic/miniforge3/envs/open_r1/lib/python3.11/site-packages/transformers/configuration_utils.py", line 594, in get_config_dict
    config_dict, kwargs = cls._get_config_dict(pretrained_model_name_or_path, **kwargs)
                          ^^^^^^^^^^^^^^^^^^^^^^^^^^^^^^^^^^^^^^^^^^^^^^^^^^^^^^^^^^^^^
  File "/home/feic/miniforge3/envs/open_r1/lib/python3.11/site-packages/transformers/configuration_utils.py", line 653, in _get_config_dict
    resolved_config_file = cached_file(
                           ^^^^^^^^^^^^
  File "/home/feic/miniforge3/envs/open_r1/lib/python3.11/site-packages/transformers/utils/hub.py", line 406, in cached_file
    raise EnvironmentError(f"There was a specific connection error when trying to load {path_or_repo_id}:\n{err}")
OSError: There was a specific connection error when trying to load Qwen/Qwen2.5-7B-Instruct:
401 Client Error: Unauthorized for url: https://huggingface.co/Qwen/Qwen2.5-7B-Instruct/resolve/main/config.json (Request ID: Root=1-680f9139-5a4fc62c17b112545aa7820f;21437377-6298-49bb-a391-33a92fa7f357)

Invalid credentials in Authorization header
