Traceback (most recent call last):
  File "/home/feic/miniforge3/envs/open_r1/lib/python3.11/site-packages/huggingface_hub/utils/_http.py", line 409, in hf_raise_for_status
    response.raise_for_status()
  File "/home/feic/miniforge3/envs/open_r1/lib/python3.11/site-packages/requests/models.py", line 1024, in raise_for_status
    raise HTTPError(http_error_msg, response=self)
requests.exceptions.HTTPError: 401 Client Error: Unauthorized for url: https://huggingface.co/gpt2-xl/resolve/main/config.json

The above exception was the direct cause of the following exception:

Traceback (most recent call last):
  File "/home/feic/miniforge3/envs/open_r1/lib/python3.11/site-packages/transformers/utils/hub.py", line 342, in cached_file
    resolved_file = hf_hub_download(
                    ^^^^^^^^^^^^^^^^
  File "/home/feic/miniforge3/envs/open_r1/lib/python3.11/site-packages/huggingface_hub/utils/_validators.py", line 114, in _inner_fn
    return fn(*args, **kwargs)
           ^^^^^^^^^^^^^^^^^^^
  File "/home/feic/miniforge3/envs/open_r1/lib/python3.11/site-packages/huggingface_hub/file_download.py", line 862, in hf_hub_download
    return _hf_hub_download_to_cache_dir(
           ^^^^^^^^^^^^^^^^^^^^^^^^^^^^^^
  File "/home/feic/miniforge3/envs/open_r1/lib/python3.11/site-packages/huggingface_hub/file_download.py", line 969, in _hf_hub_download_to_cache_dir
    _raise_on_head_call_error(head_call_error, force_download, local_files_only)
  File "/home/feic/miniforge3/envs/open_r1/lib/python3.11/site-packages/huggingface_hub/file_download.py", line 1486, in _raise_on_head_call_error
    raise head_call_error
  File "/home/feic/miniforge3/envs/open_r1/lib/python3.11/site-packages/huggingface_hub/file_download.py", line 1376, in _get_metadata_or_catch_error
    metadata = get_hf_file_metadata(
               ^^^^^^^^^^^^^^^^^^^^^
  File "/home/feic/miniforge3/envs/open_r1/lib/python3.11/site-packages/huggingface_hub/utils/_validators.py", line 114, in _inner_fn
    return fn(*args, **kwargs)
           ^^^^^^^^^^^^^^^^^^^
  File "/home/feic/miniforge3/envs/open_r1/lib/python3.11/site-packages/huggingface_hub/file_download.py", line 1296, in get_hf_file_metadata
    r = _request_wrapper(
        ^^^^^^^^^^^^^^^^^
  File "/home/feic/miniforge3/envs/open_r1/lib/python3.11/site-packages/huggingface_hub/file_download.py", line 280, in _request_wrapper
    response = _request_wrapper(
               ^^^^^^^^^^^^^^^^^
  File "/home/feic/miniforge3/envs/open_r1/lib/python3.11/site-packages/huggingface_hub/file_download.py", line 304, in _request_wrapper
    hf_raise_for_status(response)
  File "/home/feic/miniforge3/envs/open_r1/lib/python3.11/site-packages/huggingface_hub/utils/_http.py", line 481, in hf_raise_for_status
    raise _format(HfHubHTTPError, str(e), response) from e
huggingface_hub.errors.HfHubHTTPError: 401 Client Error: Unauthorized for url: https://huggingface.co/gpt2-xl/resolve/main/config.json (Request ID: Root=1-6810bc7c-74e312d571801db654f6dc1e;12a38f0f-7287-44ab-8385-543ba71d4849)

Invalid credentials in Authorization header

During handling of the above exception, another exception occurred:

Traceback (most recent call last):
  File "/home/feic/miniforge3/envs/open_r1/lib/python3.11/site-packages/pudb/__init__.py", line 176, in _runscript
    dbg._runscript(mainpyfile)
  File "/home/feic/miniforge3/envs/open_r1/lib/python3.11/site-packages/pudb/debugger.py", line 529, in _runscript
    self.run(statement)
  File "/home/feic/miniforge3/envs/open_r1/lib/python3.11/bdb.py", line 600, in run
    exec(cmd, globals, locals)
  File "<string>", line 1, in <module>
  File "metrices.py", line 105, in <module>
    calculate_perplexity(baseline_stories)
  File "metrices.py", line 36, in calculate_perplexity
    model = GPT2LMHeadModel.from_pretrained(model_name).to(device)
            ^^^^^^^^^^^^^^^^^^^^^^^^^^^^^^^^^^^^^^^^^^^
  File "/home/feic/miniforge3/envs/open_r1/lib/python3.11/site-packages/transformers/modeling_utils.py", line 262, in _wrapper
    return func(*args, **kwargs)
           ^^^^^^^^^^^^^^^^^^^^^
  File "/home/feic/miniforge3/envs/open_r1/lib/python3.11/site-packages/transformers/modeling_utils.py", line 3647, in from_pretrained
    config, model_kwargs = cls.config_class.from_pretrained(
                           ^^^^^^^^^^^^^^^^^^^^^^^^^^^^^^^^^
  File "/home/feic/miniforge3/envs/open_r1/lib/python3.11/site-packages/transformers/configuration_utils.py", line 554, in from_pretrained
    config_dict, kwargs = cls.get_config_dict(pretrained_model_name_or_path, **kwargs)
                          ^^^^^^^^^^^^^^^^^^^^^^^^^^^^^^^^^^^^^^^^^^^^^^^^^^^^^^^^^^^^
  File "/home/feic/miniforge3/envs/open_r1/lib/python3.11/site-packages/transformers/configuration_utils.py", line 594, in get_config_dict
    config_dict, kwargs = cls._get_config_dict(pretrained_model_name_or_path, **kwargs)
                          ^^^^^^^^^^^^^^^^^^^^^^^^^^^^^^^^^^^^^^^^^^^^^^^^^^^^^^^^^^^^^
  File "/home/feic/miniforge3/envs/open_r1/lib/python3.11/site-packages/transformers/configuration_utils.py", line 653, in _get_config_dict
    resolved_config_file = cached_file(
                           ^^^^^^^^^^^^
  File "/home/feic/miniforge3/envs/open_r1/lib/python3.11/site-packages/transformers/utils/hub.py", line 406, in cached_file
    raise EnvironmentError(f"There was a specific connection error when trying to load {path_or_repo_id}:\n{err}")
OSError: There was a specific connection error when trying to load gpt2-xl:
401 Client Error: Unauthorized for url: https://huggingface.co/gpt2-xl/resolve/main/config.json (Request ID: Root=1-6810bc7c-74e312d571801db654f6dc1e;12a38f0f-7287-44ab-8385-543ba71d4849)

Invalid credentials in Authorization header
